2023-12-22 14:54:14,287 - ERROR - Exception on /vinted [GET]
Traceback (most recent call last):
  File "/home/fletcher/.local/lib/python3.10/site-packages/flask/app.py", line 2528, in wsgi_app
    response = self.full_dispatch_request()
  File "/home/fletcher/.local/lib/python3.10/site-packages/flask/app.py", line 1825, in full_dispatch_request
    rv = self.handle_user_exception(e)
  File "/home/fletcher/.local/lib/python3.10/site-packages/flask/app.py", line 1823, in full_dispatch_request
    rv = self.dispatch_request()
  File "/home/fletcher/.local/lib/python3.10/site-packages/flask/app.py", line 1799, in dispatch_request
    return self.ensure_sync(self.view_functions[rule.endpoint])(**view_args)
  File "/home/fletcher/Documents/Perso/Dev/Vinted/Vinted--Tools/Api-Vinted-Python/Interface-Graphique-Java/../MainApi.py", line 71, in Vinted_last_publish
    result = myfonction.last_publish(str(link))
  File "/home/fletcher/Documents/Perso/Dev/Vinted/Vinted--Tools/Api-Vinted-Python/Fonction/last_publish.py", line 38, in last_publish
    bot = webdriver.Chrome(options=options,  executable_path="./Chrome+Webdriver/chromedriver")
  File "/home/fletcher/.local/lib/python3.10/site-packages/selenium/webdriver/chrome/webdriver.py", line 84, in __init__
    super().__init__(
  File "/home/fletcher/.local/lib/python3.10/site-packages/selenium/webdriver/chromium/webdriver.py", line 104, in __init__
    super().__init__(
  File "/home/fletcher/.local/lib/python3.10/site-packages/selenium/webdriver/remote/webdriver.py", line 286, in __init__
    self.start_session(capabilities, browser_profile)
  File "/home/fletcher/.local/lib/python3.10/site-packages/selenium/webdriver/remote/webdriver.py", line 378, in start_session
    response = self.execute(Command.NEW_SESSION, parameters)
  File "/home/fletcher/.local/lib/python3.10/site-packages/selenium/webdriver/remote/webdriver.py", line 440, in execute
    self.error_handler.check_response(response)
  File "/home/fletcher/.local/lib/python3.10/site-packages/selenium/webdriver/remote/errorhandler.py", line 245, in check_response
    raise exception_class(message, screen, stacktrace)
selenium.common.exceptions.WebDriverException: Message: unknown error: Chrome failed to start: exited abnormally.
  (unknown error: DevToolsActivePort file doesn't exist)
  (The process started from chrome location /usr/bin/google-chrome is no longer running, so ChromeDriver is assuming that Chrome has crashed.)
Stacktrace:
#0 0x55dcabeaa4e3 <unknown>
#1 0x55dcabbd9c76 <unknown>
#2 0x55dcabc02d78 <unknown>
#3 0x55dcabbff029 <unknown>
#4 0x55dcabc3dccc <unknown>
#5 0x55dcabc3d47f <unknown>
#6 0x55dcabc34de3 <unknown>
#7 0x55dcabc0a2dd <unknown>
#8 0x55dcabc0b34e <unknown>
#9 0x55dcabe6a3e4 <unknown>
#10 0x55dcabe6e3d7 <unknown>
#11 0x55dcabe78b20 <unknown>
#12 0x55dcabe6f023 <unknown>
#13 0x55dcabe3d1aa <unknown>
#14 0x55dcabe936b8 <unknown>
#15 0x55dcabe93847 <unknown>
#16 0x55dcabea3243 <unknown>
#17 0x7f6cf55beac3 <unknown>

2023-12-22 14:55:35,188 - ERROR - Exception on /vinted [GET]
Traceback (most recent call last):
  File "/home/fletcher/.local/lib/python3.10/site-packages/flask/app.py", line 2528, in wsgi_app
    response = self.full_dispatch_request()
  File "/home/fletcher/.local/lib/python3.10/site-packages/flask/app.py", line 1825, in full_dispatch_request
    rv = self.handle_user_exception(e)
  File "/home/fletcher/.local/lib/python3.10/site-packages/flask/app.py", line 1823, in full_dispatch_request
    rv = self.dispatch_request()
  File "/home/fletcher/.local/lib/python3.10/site-packages/flask/app.py", line 1799, in dispatch_request
    return self.ensure_sync(self.view_functions[rule.endpoint])(**view_args)
  File "/home/fletcher/Documents/Perso/Dev/Vinted/Vinted--Tools/Api-Vinted-Python/Interface-Graphique-Java/../MainApi.py", line 71, in Vinted_last_publish
    result = myfonction.last_publish(str(link))
  File "/home/fletcher/Documents/Perso/Dev/Vinted/Vinted--Tools/Api-Vinted-Python/Fonction/last_publish.py", line 38, in last_publish
    bot = webdriver.Chrome(options=options,  executable_path="./Chrome+Webdriver/chromedriver")
  File "/home/fletcher/.local/lib/python3.10/site-packages/selenium/webdriver/chrome/webdriver.py", line 84, in __init__
    super().__init__(
  File "/home/fletcher/.local/lib/python3.10/site-packages/selenium/webdriver/chromium/webdriver.py", line 104, in __init__
    super().__init__(
  File "/home/fletcher/.local/lib/python3.10/site-packages/selenium/webdriver/remote/webdriver.py", line 286, in __init__
    self.start_session(capabilities, browser_profile)
  File "/home/fletcher/.local/lib/python3.10/site-packages/selenium/webdriver/remote/webdriver.py", line 378, in start_session
    response = self.execute(Command.NEW_SESSION, parameters)
  File "/home/fletcher/.local/lib/python3.10/site-packages/selenium/webdriver/remote/webdriver.py", line 440, in execute
    self.error_handler.check_response(response)
  File "/home/fletcher/.local/lib/python3.10/site-packages/selenium/webdriver/remote/errorhandler.py", line 245, in check_response
    raise exception_class(message, screen, stacktrace)
selenium.common.exceptions.WebDriverException: Message: unknown error: Chrome failed to start: exited abnormally.
  (unknown error: DevToolsActivePort file doesn't exist)
  (The process started from chrome location /usr/bin/google-chrome is no longer running, so ChromeDriver is assuming that Chrome has crashed.)
Stacktrace:
#0 0x55ee60c864e3 <unknown>
#1 0x55ee609b5c76 <unknown>
#2 0x55ee609ded78 <unknown>
#3 0x55ee609db029 <unknown>
#4 0x55ee60a19ccc <unknown>
#5 0x55ee60a1947f <unknown>
#6 0x55ee60a10de3 <unknown>
#7 0x55ee609e62dd <unknown>
#8 0x55ee609e734e <unknown>
#9 0x55ee60c463e4 <unknown>
#10 0x55ee60c4a3d7 <unknown>
#11 0x55ee60c54b20 <unknown>
#12 0x55ee60c4b023 <unknown>
#13 0x55ee60c191aa <unknown>
#14 0x55ee60c6f6b8 <unknown>
#15 0x55ee60c6f847 <unknown>
#16 0x55ee60c7f243 <unknown>
#17 0x7fc9ab6e7ac3 <unknown>

2023-12-22 14:57:13,005 - ERROR - Exception on /vinted [GET]
Traceback (most recent call last):
  File "/home/fletcher/.local/lib/python3.10/site-packages/flask/app.py", line 2528, in wsgi_app
    response = self.full_dispatch_request()
  File "/home/fletcher/.local/lib/python3.10/site-packages/flask/app.py", line 1825, in full_dispatch_request
    rv = self.handle_user_exception(e)
  File "/home/fletcher/.local/lib/python3.10/site-packages/flask/app.py", line 1823, in full_dispatch_request
    rv = self.dispatch_request()
  File "/home/fletcher/.local/lib/python3.10/site-packages/flask/app.py", line 1799, in dispatch_request
    return self.ensure_sync(self.view_functions[rule.endpoint])(**view_args)
  File "/home/fletcher/Documents/Perso/Dev/Vinted/Vinted--Tools/Api-Vinted-Python/Interface-Graphique-Java/../MainApi.py", line 71, in Vinted_last_publish
    result = myfonction.last_publish(str(link))
  File "/home/fletcher/Documents/Perso/Dev/Vinted/Vinted--Tools/Api-Vinted-Python/Fonction/last_publish.py", line 38, in last_publish
    bot = webdriver.Chrome(options=options,  executable_path="./Chrome+Webdriver/chromedriver")
  File "/home/fletcher/.local/lib/python3.10/site-packages/selenium/webdriver/chrome/webdriver.py", line 84, in __init__
    super().__init__(
  File "/home/fletcher/.local/lib/python3.10/site-packages/selenium/webdriver/chromium/webdriver.py", line 104, in __init__
    super().__init__(
  File "/home/fletcher/.local/lib/python3.10/site-packages/selenium/webdriver/remote/webdriver.py", line 286, in __init__
    self.start_session(capabilities, browser_profile)
  File "/home/fletcher/.local/lib/python3.10/site-packages/selenium/webdriver/remote/webdriver.py", line 378, in start_session
    response = self.execute(Command.NEW_SESSION, parameters)
  File "/home/fletcher/.local/lib/python3.10/site-packages/selenium/webdriver/remote/webdriver.py", line 440, in execute
    self.error_handler.check_response(response)
  File "/home/fletcher/.local/lib/python3.10/site-packages/selenium/webdriver/remote/errorhandler.py", line 245, in check_response
    raise exception_class(message, screen, stacktrace)
selenium.common.exceptions.WebDriverException: Message: unknown error: Chrome failed to start: exited normally.
  (unknown error: DevToolsActivePort file doesn't exist)
  (The process started from chrome location /usr/bin/google-chrome is no longer running, so ChromeDriver is assuming that Chrome has crashed.)
Stacktrace:
#0 0x557a48a5c4e3 <unknown>
#1 0x557a4878bc76 <unknown>
#2 0x557a487b4d78 <unknown>
#3 0x557a487b1029 <unknown>
#4 0x557a487efccc <unknown>
#5 0x557a487ef47f <unknown>
#6 0x557a487e6de3 <unknown>
#7 0x557a487bc2dd <unknown>
#8 0x557a487bd34e <unknown>
#9 0x557a48a1c3e4 <unknown>
#10 0x557a48a203d7 <unknown>
#11 0x557a48a2ab20 <unknown>
#12 0x557a48a21023 <unknown>
#13 0x557a489ef1aa <unknown>
#14 0x557a48a456b8 <unknown>
#15 0x557a48a45847 <unknown>
#16 0x557a48a55243 <unknown>
#17 0x7fb1789c8ac3 <unknown>

